<mujoco model="Humanoid and 100 objects">
  <!-- Degree of Freedom: 627
     Actuators: 21

     Humanoid and 100 free primitive objects.
-->
  <compiler angle="radian" autolimits="true"/>
  <option timestep="0.005"/>
  <size memory="100M"/>
  <visual>
    <global offwidth="800" offheight="800"/>
    <quality offsamples="8"/>
    <map force="0.05" znear="0.1" zfar="30"/>
    <rgba haze="0.15 0.25 0.35 1"/>
  </visual>
  <statistic extent="4"/>
  <default class="main">
    <geom solimp="0.9 0.9 0.01 0.5 2"/>
    <general ctrllimited="true" ctrlrange="-1 1"/>
    <default class="body">
      <joint limited="true" solimplimit="0 0.99 0.01 0.5 2" stiffness="1" armature="0.01" damping="0.2"/>
      <geom type="capsule" condim="1" friction="0.7 0.005 0.0001" solref="0.015 1" solimp="0.9 0.99 0.003 0.5 2" material="body"/>
      <default class="big_joint">
        <joint stiffness="10" damping="5"/>
        <default class="big_stiff_joint">
          <joint stiffness="20"/>
        </default>
      </default>
    </default>
    <default class="object1">
      <geom size="0.1 0.05 0" type="capsule" material="object1"/>
    </default>
    <default class="object2">
      <geom size="0.15 0.1 0.07" type="ellipsoid" material="object2"/>
    </default>
    <default class="object3">
      <geom size="0.15 0.1 0.05" type="box" material="object3"/>
    </default>
    <default class="object4">
      <geom size="0.1 0.05 0" type="cylinder" condim="4" friction="1 0.01 0.01" material="object4"/>
    </default>
    <default class="object5">
      <geom size="0.1 0 0" material="object5"/>
    </default>
    <default class="border">
      <geom size="0.4 0 0" type="capsule" rgba="0.4 0.4 0.4 1"/>
    </default>
    <default class="borderpost">
      <geom size="0.41 0.41 0.41" type="box" rgba="0.55 0.55 0.55 1"/>
    </default>
  </default>
  <asset>
    <texture type="skybox" builtin="gradient" rgb1="0.3 0.5 0.7" rgb2="0 0 0" width="512" height="3072"/>
    <texture type="cube" name="body" builtin="flat" mark="cross" rgb1="0.8 0.6 0.4" rgb2="0.8 0.6 0.4" markrgb="1 1 1" width="128" height="768"/>
    <texture type="2d" name="grid" builtin="checker" rgb1="0.1 0.2 0.3" rgb2="0.2 0.3 0.4" width="512" height="512"/>
    <texture type="skybox" builtin="gradient" rgb1="0.4 0.6 0.8" rgb2="0 0 0" width="512" height="3072"/>
    <texture type="cube" name="texgeom" builtin="flat" mark="cross" rgb1="0.6 0.6 0.6" rgb2="0.6 0.6 0.6" markrgb="1 1 1" width="128" height="768"/>
    <texture type="2d" name="texplane" builtin="checker" rgb1="0.4 0.4 0.4" rgb2="0.6 0.6 0.6" width="512" height="512"/>
    <material name="body" texture="body" texuniform="true" rgba="0.8 0.6 0.4 1"/>
    <material name="grid" texture="grid" texuniform="true" reflectance="0.2"/>
    <material name="MatPlane" texture="texplane" texuniform="true" reflectance="0.3" rgba="0.7 0.7 0.7 1"/>
    <material name="object1" texture="texgeom" texuniform="true" rgba="0.4 0.9 0.6 1"/>
    <material name="object2" texture="texgeom" texuniform="true" rgba="0.4 0.6 0.9 1"/>
    <material name="object3" texture="texgeom" texuniform="true" rgba="0.4 0.9 0.9 1"/>
    <material name="object4" texture="texgeom" texuniform="true" rgba="0.8 0.6 0.8 1"/>
    <material name="object5" texture="texgeom" texuniform="true" rgba="0.9 0.1 0.1 1"/>
  </asset>
  <worldbody>
    <geom name="floor" size="3 3 0.5" type="plane" material="MatPlane"/>
    <geom class="border" size="0.4 3" pos="0 3 0" quat="0.707107 0 -0.707107 0"/>
    <geom class="border" size="0.4 3" pos="0 -3 0" quat="0.707107 0 -0.707107 0"/>
    <geom class="border" size="0.4 3" pos="3 0 0" quat="0.707107 -0.707107 0 0"/>
    <geom class="border" size="0.4 3" pos="-3 0 0" quat="0.707107 -0.707107 0 0"/>
    <geom class="borderpost" pos="3 3 0"/>
    <geom class="borderpost" pos="-3 3 0"/>
    <geom class="borderpost" pos="3 -3 0"/>
    <geom class="borderpost" pos="-3 -3 0"/>
    <light pos="0 0 10" dir="0 0 -1" directional="true" diffuse="0.8 0.8 0.8"/>
    <body name="torso" childclass="body" pos="0 0 1.5">
      <joint name="root" limited="false" type="free" solimplimit="0.9 0.95 0.001 0.5 2" stiffness="0" armature="0" damping="0"/>
      <geom name="torso" size="0.07 0.07" quat="0.707107 0.707107 0 0"/>
      <geom name="upper_waist" size="0.06 0.06" pos="-0.01 0 -0.12" quat="0.707107 0.707107 0 0"/>
      <camera name="back" pos="-3 0 1" quat="0.601501 0.371748 -0.371748 -0.601501" mode="trackcom"/>
      <camera name="side" pos="0 -3 1" quat="0.850651 0.525731 0 0" mode="trackcom"/>
      <light name="top" pos="0 0 2" dir="0 0 -1" mode="trackcom"/>
      <body name="head" pos="0 0 0.19">
        <geom name="head" size="0.09" type="sphere"/>
        <camera name="egocentric" pos="0.09 0 0" quat="0.524286 0.474472 -0.474472 -0.524286" fovy="80"/>
      </body>
      <body name="lower_waist" pos="-0.01 0 -0.26">
        <joint name="abdomen_z" class="big_stiff_joint" pos="0 0 0.065" axis="0 0 1" range="-0.785398 0.785398"/>
        <joint name="abdomen_y" class="big_joint" pos="0 0 0.065" axis="0 1 0" range="-1.309 0.523599"/>
        <geom name="lower_waist" size="0.06 0.06" quat="0.707107 0.707107 0 0"/>
        <body name="pelvis" pos="0 0 -0.165">
          <joint name="abdomen_x" class="big_joint" pos="0 0 0.1" axis="1 0 0" range="-0.610865 0.610865"/>
          <geom name="butt" size="0.09 0.07" pos="-0.02 0 0" quat="0.707107 0.707107 0 0"/>
          <body name="right_thigh" pos="0 -0.1 -0.04">
            <joint name="right_hip_x" class="big_joint" pos="0 0 0" axis="1 0 0" range="-0.436332 0.0872665"/>
            <joint name="right_hip_z" class="big_joint" pos="0 0 0" axis="0 0 1" range="-1.0472 0.610865"/>
            <joint name="right_hip_y" class="big_stiff_joint" pos="0 0 0" axis="0 1 0" range="-1.91986 0.349066"/>
            <geom name="right_thigh" size="0.06 0.170074" pos="0 0.005 -0.17" quat="0.999892 0.0147011 0 0"/>
            <body name="right_shin" pos="0 0.01 -0.403">
              <joint name="right_knee" pos="0 0 0.02" axis="0 -1 0" range="-2.79253 0.0349066"/>
              <geom name="right_shin" size="0.049 0.15" pos="0 0 -0.15"/>
              <body name="right_foot" pos="0 0 -0.39">
                <joint name="right_ankle_y" pos="0 0 0.08" axis="0 1 0" stiffness="6" range="-0.872665 0.872665"/>
                <joint name="right_ankle_x" pos="0 0 0.04" axis="0.894427 0 0.447214" stiffness="3" range="-0.872665 0.872665"/>
                <geom name="right_right_foot" size="0.027 0.105475" pos="0.035 -0.03 0" quat="0.707107 -0.0670402 -0.703922 0"/>
                <geom name="left_right_foot" size="0.027 0.105475" pos="0.035 0.01 0" quat="0.707107 0.0670402 -0.703922 0"/>
              </body>
            </body>
          </body>
          <body name="left_thigh" pos="0 0.1 -0.04">
            <joint name="left_hip_x" class="big_joint" pos="0 0 0" axis="-1 0 0" range="-0.436332 0.0872665"/>
            <joint name="left_hip_z" class="big_joint" pos="0 0 0" axis="0 0 -1" range="-1.0472 0.610865"/>
            <joint name="left_hip_y" class="big_stiff_joint" pos="0 0 0" axis="0 1 0" range="-1.91986 0.349066"/>
            <geom name="left_thigh" size="0.06 0.170074" pos="0 -0.005 -0.17" quat="0.999892 -0.0147011 0 0"/>
            <body name="left_shin" pos="0 -0.01 -0.403">
              <joint name="left_knee" pos="0 0 0.02" axis="0 -1 0" range="-2.79253 0.0349066"/>
              <geom name="left_shin" size="0.049 0.15" pos="0 0 -0.15"/>
              <body name="left_foot" pos="0 0 -0.39">
                <joint name="left_ankle_y" pos="0 0 0.08" axis="0 1 0" stiffness="6" range="-0.872665 0.872665"/>
                <joint name="left_ankle_x" pos="0 0 0.04" axis="0.894427 0 0.447214" stiffness="3" range="-0.872665 0.872665"/>
                <geom name="left_left_foot" size="0.027 0.105475" pos="0.035 0.03 0" quat="0.707107 0.0670402 -0.703922 0"/>
                <geom name="right_left_foot" size="0.027 0.105475" pos="0.035 -0.01 0" quat="0.707107 -0.0670402 -0.703922 0"/>
              </body>
            </body>
          </body>
        </body>
      </body>
      <body name="right_upper_arm" pos="0 -0.17 0.06">
        <joint name="right_shoulder1" pos="0 0 0" axis="0.816497 0.408248 0.408248" range="-1.48353 1.0472"/>
        <joint name="right_shoulder2" pos="0 0 0" axis="0 -0.707107 0.707107" range="-1.48353 1.0472"/>
        <geom name="right_upper_arm" size="0.04 0.138564" pos="0.08 -0.08 -0.08" quat="0.888074 -0.325058 -0.325058 0"/>
        <body name="right_lower_arm" pos="0.18 -0.18 -0.18">
          <joint name="right_elbow" pos="0 0 0" axis="0 -0.707107 0.707107" stiffness="0" range="-1.5708 0.872665"/>
          <geom name="right_lower_arm" size="0.031 0.138564" pos="0.09 0.09 0.09" quat="0.459701 0.627963 -0.627963 0"/>
          <body name="right_hand" pos="0.18 0.18 0.18">
            <geom name="right_hand" size="0.04" quat="0.888074 -0.325058 0.325058 0" type="sphere"/>
          </body>
        </body>
      </body>
      <body name="left_upper_arm" pos="0 0.17 0.06">
        <joint name="left_shoulder1" pos="0 0 0" axis="0.816497 -0.408248 0.408248" range="-1.0472 1.48353"/>
        <joint name="left_shoulder2" pos="0 0 0" axis="0 0.707107 0.707107" range="-1.0472 1.48353"/>
        <geom name="left_upper_arm" size="0.04 0.138564" pos="0.08 0.08 -0.08" quat="0.888074 0.325058 -0.325058 0"/>
        <body name="left_lower_arm" pos="0.18 0.18 -0.18">
          <joint name="left_elbow" pos="0 0 0" axis="0 -0.707107 -0.707107" stiffness="0" range="-1.5708 0.872665"/>
          <geom name="left_lower_arm" size="0.031 0.138564" pos="0.09 -0.09 0.09" quat="0.459701 -0.627963 -0.627963 0"/>
          <body name="left_hand" pos="0.18 -0.18 0.18">
            <geom name="left_hand" size="0.04" quat="0.888074 0.325058 0.325058 0" type="sphere"/>
          </body>
        </body>
      </body>
    </body>
    <body pos="-2 -2 1" quat="-0.632456 -0.632456 0.316228 0.316228">
      <joint type="free"/>
      <geom class="object1"/>
    </body>
    <body pos="-2 -2 2" quat="-0.5547 -0.5547 0.5547 0.27735">
      <joint type="free"/>
      <geom class="object1"/>
    </body>
    <body pos="-2 -2 3" quat="-0.471405 -0.471405 0.707107 0.235702">
      <joint type="free"/>
      <geom class="object1"/>
    </body>
    <body pos="-2 -2 4" quat="-0.471405 -0.471405 0.707107 0.235702">
      <joint type="free"/>
      <geom class="object1"/>
    </body>
    <body pos="-2 -1 1" quat="-0.755929 -0.377964 0.377964 0.377964">
      <joint type="free"/>
      <geom class="object1"/>
    </body>
    <body pos="-2 -1 2" quat="-0.632456 -0.316228 0.632456 0.316228">
      <joint type="free"/>
      <geom class="object1"/>
    </body>
    <body pos="-2 -1 3" quat="-0.516398 -0.258199 0.774597 0.258199">
      <joint type="free"/>
      <geom class="object1"/>
    </body>
    <body pos="-2 -1 4" quat="-0.516398 -0.258199 0.774597 0.258199">
      <joint type="free"/>
      <geom class="object1"/>
    </body>
    <body pos="-2 0 1" quat="-0.816497 0 0.408248 0.408248">
      <joint type="free"/>
      <geom class="object1"/>
    </body>
    <body pos="-2 0 2" quat="-0.666667 0 0.666667 0.333333">
      <joint type="free"/>
      <geom class="object1"/>
    </body>
    <body pos="-2 0 3" quat="-0.534522 0 0.801784 0.267261">
      <joint type="free"/>
      <geom class="object1"/>
    </body>
    <body pos="-2 0 4" quat="-0.534522 0 0.801784 0.267261">
      <joint type="free"/>
      <geom class="object1"/>
    </body>
    <body pos="-2 1 1" quat="-0.755929 0.377964 0.377964 0.377964">
      <joint type="free"/>
      <geom class="object1"/>
    </body>
    <body pos="-2 1 2" quat="-0.632456 0.316228 0.632456 0.316228">
      <joint type="free"/>
      <geom class="object1"/>
    </body>
    <body pos="-2 1 3" quat="-0.516398 0.258199 0.774597 0.258199">
      <joint type="free"/>
      <geom class="object1"/>
    </body>
    <body pos="-2 1 4" quat="-0.516398 0.258199 0.774597 0.258199">
      <joint type="free"/>
      <geom class="object1"/>
    </body>
    <body pos="-2 2 1" quat="-0.632456 0.632456 0.316228 0.316228">
      <joint type="free"/>
      <geom class="object1"/>
    </body>
    <body pos="-2 2 2" quat="-0.5547 0.5547 0.5547 0.27735">
      <joint type="free"/>
      <geom class="object1"/>
    </body>
    <body pos="-2 2 3" quat="-0.471405 0.471405 0.707107 0.235702">
      <joint type="free"/>
      <geom class="object1"/>
    </body>
    <body pos="-2 2 4" quat="-0.471405 0.471405 0.707107 0.235702">
      <joint type="free"/>
      <geom class="object1"/>
    </body>
    <body pos="-1 -2 1" quat="-0.377964 -0.755929 0.377964 0.377964">
      <joint type="free"/>
      <geom class="object2"/>
    </body>
    <body pos="-1 -2 2" quat="-0.316228 -0.632456 0.632456 0.316228">
      <joint type="free"/>
      <geom class="object2"/>
    </body>
    <body pos="-1 -2 3" quat="-0.258199 -0.516398 0.774597 0.258199">
      <joint type="free"/>
      <geom class="object2"/>
    </body>
    <body pos="-1 -2 4" quat="-0.258199 -0.516398 0.774597 0.258199">
      <joint type="free"/>
      <geom class="object2"/>
    </body>
    <body pos="-1 -1 1" quat="-0.5 -0.5 0.5 0.5">
      <joint type="free"/>
      <geom class="object2"/>
    </body>
    <body pos="-1 -1 2" quat="-0.377964 -0.377964 0.755929 0.377964">
      <joint type="free"/>
      <geom class="object2"/>
    </body>
    <body pos="-1 -1 3" quat="-0.288675 -0.288675 0.866025 0.288675">
      <joint type="free"/>
      <geom class="object2"/>
    </body>
    <body pos="-1 -1 4" quat="-0.288675 -0.288675 0.866025 0.288675">
      <joint type="free"/>
      <geom class="object2"/>
    </body>
    <body pos="-1 0 1" quat="-0.57735 0 0.57735 0.57735">
      <joint type="free"/>
      <geom class="object2"/>
    </body>
    <body pos="-1 0 2" quat="-0.408248 0 0.816497 0.408248">
      <joint type="free"/>
      <geom class="object2"/>
    </body>
    <body pos="-1 0 3" quat="-0.301511 0 0.904534 0.301511">
      <joint type="free"/>
      <geom class="object2"/>
    </body>
    <body pos="-1 0 4" quat="-0.301511 0 0.904534 0.301511">
      <joint type="free"/>
      <geom class="object2"/>
    </body>
    <body pos="-1 1 1" quat="-0.5 0.5 0.5 0.5">
      <joint type="free"/>
      <geom class="object2"/>
    </body>
    <body pos="-1 1 2" quat="-0.377964 0.377964 0.755929 0.377964">
      <joint type="free"/>
      <geom class="object2"/>
    </body>
    <body pos="-1 1 3" quat="-0.288675 0.288675 0.866025 0.288675">
      <joint type="free"/>
      <geom class="object2"/>
    </body>
    <body pos="-1 1 4" quat="-0.288675 0.288675 0.866025 0.288675">
      <joint type="free"/>
      <geom class="object2"/>
    </body>
    <body pos="-1 2 1" quat="-0.377964 0.755929 0.377964 0.377964">
      <joint type="free"/>
      <geom class="object2"/>
    </body>
    <body pos="-1 2 2" quat="-0.316228 0.632456 0.632456 0.316228">
      <joint type="free"/>
      <geom class="object2"/>
    </body>
    <body pos="-1 2 3" quat="-0.258199 0.516398 0.774597 0.258199">
      <joint type="free"/>
      <geom class="object2"/>
    </body>
    <body pos="-1 2 4" quat="-0.258199 0.516398 0.774597 0.258199">
      <joint type="free"/>
      <geom class="object2"/>
    </body>
    <body pos="0 -2 1" quat="0 -0.816497 0.408248 0.408248">
      <joint type="free"/>
      <geom class="object3"/>
    </body>
    <body pos="0 -2 2" quat="0 -0.666667 0.666667 0.333333">
      <joint type="free"/>
      <geom class="object3"/>
    </body>
    <body pos="0 -2 3" quat="0 -0.534522 0.801784 0.267261">
      <joint type="free"/>
      <geom class="object3"/>
    </body>
    <body pos="0 -2 4" quat="0 -0.534522 0.801784 0.267261">
      <joint type="free"/>
      <geom class="object3"/>
    </body>
    <body pos="0 -1 1" quat="0 -0.57735 0.57735 0.57735">
      <joint type="free"/>
      <geom class="object3"/>
    </body>
    <body pos="0 -1 2" quat="0 -0.408248 0.816497 0.408248">
      <joint type="free"/>
      <geom class="object3"/>
    </body>
    <body pos="0 -1 3" quat="0 -0.301511 0.904534 0.301511">
      <joint type="free"/>
      <geom class="object3"/>
    </body>
    <body pos="0 -1 4" quat="0 -0.301511 0.904534 0.301511">
      <joint type="free"/>
      <geom class="object3"/>
    </body>
    <body pos="0.3 0 1" quat="0 0 0.707107 0.707107">
      <joint type="free"/>
      <geom class="object3"/>
    </body>
    <body pos="0 0 2" quat="0 0 0.894427 0.447214">
      <joint type="free"/>
      <geom class="object3"/>
    </body>
    <body pos="0 0 3" quat="0 0 0.948683 0.316228">
      <joint type="free"/>
      <geom class="object3"/>
    </body>
    <body pos="0 0 4" quat="0 0 0.948683 0.316228">
      <joint type="free"/>
      <geom class="object3"/>
    </body>
    <body pos="0 1 1" quat="0 0.57735 0.57735 0.57735">
      <joint type="free"/>
      <geom class="object3"/>
    </body>
    <body pos="0 1 2" quat="0 0.408248 0.816497 0.408248">
      <joint type="free"/>
      <geom class="object3"/>
    </body>
    <body pos="0 1 3" quat="0 0.301511 0.904534 0.301511">
      <joint type="free"/>
      <geom class="object3"/>
    </body>
    <body pos="0 1 4" quat="0 0.301511 0.904534 0.301511">
      <joint type="free"/>
      <geom class="object3"/>
    </body>
    <body pos="0 2 1" quat="0 0.816497 0.408248 0.408248">
      <joint type="free"/>
      <geom class="object3"/>
    </body>
    <body pos="0 2 2" quat="0 0.666667 0.666667 0.333333">
      <joint type="free"/>
      <geom class="object3"/>
    </body>
    <body pos="0 2 3" quat="0 0.534522 0.801784 0.267261">
      <joint type="free"/>
      <geom class="object3"/>
    </body>
    <body pos="0 2 4" quat="0 0.534522 0.801784 0.267261">
      <joint type="free"/>
      <geom class="object3"/>
    </body>
    <body pos="1 -2 1" quat="0.377964 -0.755929 0.377964 0.377964">
      <joint type="free"/>
      <geom class="object4"/>
    </body>
    <body pos="1 -2 2" quat="0.316228 -0.632456 0.632456 0.316228">
      <joint type="free"/>
      <geom class="object4"/>
    </body>
    <body pos="1 -2 3" quat="0.258199 -0.516398 0.774597 0.258199">
      <joint type="free"/>
      <geom class="object4"/>
    </body>
    <body pos="1 -2 4" quat="0.258199 -0.516398 0.774597 0.258199">
      <joint type="free"/>
      <geom class="object4"/>
    </body>
    <body pos="1 -1 1" quat="0.5 -0.5 0.5 0.5">
      <joint type="free"/>
      <geom class="object4"/>
    </body>
    <body pos="1 -1 2" quat="0.377964 -0.377964 0.755929 0.377964">
      <joint type="free"/>
      <geom class="object4"/>
    </body>
    <body pos="1 -1 3" quat="0.288675 -0.288675 0.866025 0.288675">
      <joint type="free"/>
      <geom class="object4"/>
    </body>
    <body pos="1 -1 4" quat="0.288675 -0.288675 0.866025 0.288675">
      <joint type="free"/>
      <geom class="object4"/>
    </body>
    <body pos="1 0 1" quat="0.57735 0 0.57735 0.57735">
      <joint type="free"/>
      <geom class="object4"/>
    </body>
    <body pos="1 0 2" quat="0.408248 0 0.816497 0.408248">
      <joint type="free"/>
      <geom class="object4"/>
    </body>
    <body pos="1 0 3" quat="0.301511 0 0.904534 0.301511">
      <joint type="free"/>
      <geom class="object4"/>
    </body>
    <body pos="1 0 4" quat="0.301511 0 0.904534 0.301511">
      <joint type="free"/>
      <geom class="object4"/>
    </body>
    <body pos="1 1 1" quat="0.5 0.5 0.5 0.5">
      <joint type="free"/>
      <geom class="object4"/>
    </body>
    <body pos="1 1 2" quat="0.377964 0.377964 0.755929 0.377964">
      <joint type="free"/>
      <geom class="object4"/>
    </body>
    <body pos="1 1 3" quat="0.288675 0.288675 0.866025 0.288675">
      <joint type="free"/>
      <geom class="object4"/>
    </body>
    <body pos="1 1 4" quat="0.288675 0.288675 0.866025 0.288675">
      <joint type="free"/>
      <geom class="object4"/>
    </body>
    <body pos="1 2 1" quat="0.377964 0.755929 0.377964 0.377964">
      <joint type="free"/>
      <geom class="object4"/>
    </body>
    <body pos="1 2 2" quat="0.316228 0.632456 0.632456 0.316228">
      <joint type="free"/>
      <geom class="object4"/>
    </body>
    <body pos="1 2 3" quat="0.258199 0.516398 0.774597 0.258199">
      <joint type="free"/>
      <geom class="object4"/>
    </body>
    <body pos="1 2 4" quat="0.258199 0.516398 0.774597 0.258199">
      <joint type="free"/>
      <geom class="object4"/>
    </body>
    <body pos="2 -2 1" quat="0.632456 -0.632456 0.316228 0.316228">
      <joint type="free"/>
      <geom class="object5"/>
    </body>
    <body pos="2 -2 2" quat="0.5547 -0.5547 0.5547 0.27735">
      <joint type="free"/>
      <geom class="object5"/>
    </body>
    <body pos="2 -2 3" quat="0.471405 -0.471405 0.707107 0.235702">
      <joint type="free"/>
      <geom class="object5"/>
    </body>
    <body pos="2 -2 4" quat="0.471405 -0.471405 0.707107 0.235702">
      <joint type="free"/>
      <geom class="object5"/>
    </body>
    <body pos="2 -1 1" quat="0.755929 -0.377964 0.377964 0.377964">
      <joint type="free"/>
      <geom class="object5"/>
    </body>
    <body pos="2 -1 2" quat="0.632456 -0.316228 0.632456 0.316228">
      <joint type="free"/>
      <geom class="object5"/>
    </body>
    <body pos="2 -1 3" quat="0.516398 -0.258199 0.774597 0.258199">
      <joint type="free"/>
      <geom class="object5"/>
    </body>
    <body pos="2 -1 4" quat="0.516398 -0.258199 0.774597 0.258199">
      <joint type="free"/>
      <geom class="object5"/>
    </body>
    <body pos="2 0 1" quat="0.816497 0 0.408248 0.408248">
      <joint type="free"/>
      <geom class="object5"/>
    </body>
    <body pos="2 0 2" quat="0.666667 0 0.666667 0.333333">
      <joint type="free"/>
      <geom class="object5"/>
    </body>
    <body pos="2 0 3" quat="0.534522 0 0.801784 0.267261">
      <joint type="free"/>
      <geom class="object5"/>
    </body>
    <body pos="2 0 4" quat="0.534522 0 0.801784 0.267261">
      <joint type="free"/>
      <geom class="object5"/>
    </body>
    <body pos="2 1 1" quat="0.755929 0.377964 0.377964 0.377964">
      <joint type="free"/>
      <geom class="object5"/>
    </body>
    <body pos="2 1 2" quat="0.632456 0.316228 0.632456 0.316228">
      <joint type="free"/>
      <geom class="object5"/>
    </body>
    <body pos="2 1 3" quat="0.516398 0.258199 0.774597 0.258199">
      <joint type="free"/>
      <geom class="object5"/>
    </body>
    <body pos="2 1 4" quat="0.516398 0.258199 0.774597 0.258199">
      <joint type="free"/>
      <geom class="object5"/>
    </body>
    <body pos="2 2 1" quat="0.632456 0.632456 0.316228 0.316228">
      <joint type="free"/>
      <geom class="object5"/>
    </body>
    <body pos="2 2 2" quat="0.5547 0.5547 0.5547 0.27735">
      <joint type="free"/>
      <geom class="object5"/>
    </body>
    <body pos="2 2 3" quat="0.471405 0.471405 0.707107 0.235702">
      <joint type="free"/>
      <geom class="object5"/>
    </body>
    <body pos="2 2 4" quat="0.471405 0.471405 0.707107 0.235702">
      <joint type="free"/>
      <geom class="object5"/>
    </body>
  </worldbody>
  <actuator>
    <general name="abdomen_y" joint="abdomen_y" gear="40 0 0 0 0 0"/>
    <general name="abdomen_z" joint="abdomen_z" gear="40 0 0 0 0 0"/>
    <general name="abdomen_x" joint="abdomen_x" gear="40 0 0 0 0 0"/>
    <general name="right_hip_x" joint="right_hip_x" gear="40 0 0 0 0 0"/>
    <general name="right_hip_z" joint="right_hip_z" gear="40 0 0 0 0 0"/>
    <general name="right_hip_y" joint="right_hip_y" gear="120 0 0 0 0 0"/>
    <general name="right_knee" joint="right_knee" gear="80 0 0 0 0 0"/>
    <general name="right_ankle_x" joint="right_ankle_x" gear="20 0 0 0 0 0"/>
    <general name="right_ankle_y" joint="right_ankle_y" gear="20 0 0 0 0 0"/>
    <general name="left_hip_x" joint="left_hip_x" gear="40 0 0 0 0 0"/>
    <general name="left_hip_z" joint="left_hip_z" gear="40 0 0 0 0 0"/>
    <general name="left_hip_y" joint="left_hip_y" gear="120 0 0 0 0 0"/>
    <general name="left_knee" joint="left_knee" gear="80 0 0 0 0 0"/>
    <general name="left_ankle_x" joint="left_ankle_x" gear="20 0 0 0 0 0"/>
    <general name="left_ankle_y" joint="left_ankle_y" gear="20 0 0 0 0 0"/>
    <general name="right_shoulder1" joint="right_shoulder1" gear="20 0 0 0 0 0"/>
    <general name="right_shoulder2" joint="right_shoulder2" gear="20 0 0 0 0 0"/>
    <general name="right_elbow" joint="right_elbow" gear="40 0 0 0 0 0"/>
    <general name="left_shoulder1" joint="left_shoulder1" gear="20 0 0 0 0 0"/>
    <general name="left_shoulder2" joint="left_shoulder2" gear="20 0 0 0 0 0"/>
    <general name="left_elbow" joint="left_elbow" gear="40 0 0 0 0 0"/>
  </actuator>
</mujoco>
