<mujoco model="rover4We (v0.2)">

    <compiler inertiafromgeom="true" angle="degree"/>
	<option	timestep="0.02" gravity="0 0 -9.81"/>
	
	<asset>
		<material name="MatWheel" specular="1" rgba=".1 .1 .1 1"/>
		<material name="MatBody" specular="1" rgba=".6 .6 .1 1"/>
        <mesh file = "/home/richie/VEX/Sim/sdk/sim_vexv5/media/Models/Fields/OverUnder/over_under_field_flat.obj"/>
	</asset>
	
	<default>
		<!--making every geom collidable. expect those that dont are default-->
		<geom contype="1" conaffinity="1"/>
	</default>
	
	<default class="acker_solver_param">
		<!--solver impedance and reference(?) for ackerman equality constraint-->
		<!--default solimp: "0.900 0.950 0.001"-->
		<!--default solref: "0.020 1.000"-->
		<!--solref: (timeconst, dampratio)
			b = 2 / (dmax * timeconst)
			k = d(r) / (dmax * dmax * timeconst * timeconst * dampratio * dampratio)
		-->
		<equality solimp="0.9950 0.9990 0.0001" solref="0.0100 0.7500"/>
	</default>
	
	<visual>
		<headlight active="1"/>
		<scale camera=".5"/>
		<map znear="0.001" zfar="1000"/>
	</visual>
	
    <worldbody>
		<body>
                <geom type="mesh" mesh="over_under_field_flat"/>
    			<!-- <geom type="box" pos="-10 0 0" size="5 5 50" rgba="1 1 1 1"/> -->
		</body>
		<body name="rover" pos="0 0 0">
		
			<light name="lamp" active="true" directional="true" cutoff="4" exponent="20" diffuse="1 1 1" specular="0 0 0" pos="0 0 2.5" dir="0 0 -1 "/>
			
			<camera name="first-person" mode="fixed" pos=".22 0 .08" euler="180 -133 -90" fovy="90"/>
			
			<joint name="centroid" type="free" pos="0 0 0"/>
             <geom name="rover-body" type="box" pos="0 0 0" size="0.2 0.15 .095" mass="12" material="MatBody"/>
			<site type="box" size=".01 .07 .07" pos=".2 0 0"/>
            <body name="r-l-wheel" pos="-0.2 0.15 -0.15">
                <joint name="r-l-drive-hinge" type="hinge" pos="0 0 0" axis="0 1 0" damping="0.01" />
                <geom type="cylinder" size=".05" fromto="0 0 0 0 0.05 0" mass=".125" material="MatWheel" condim="4"/>
				<site size=".01" pos="0 .05 .03"/>
				<site size=".01" pos="0 .05 -.03"/>
				<site size=".01" pos="0 0 .03"/>
				<site size=".01" pos="0 0 -.03"/>
            </body>
            <body name="r-r-wheel" pos="-0.2 -0.15 -0.15">
                <joint name="r-r-drive-hinge" type="hinge" pos="0 0 0" axis="0 1 0" damping="0.01"/>
                <geom type="cylinder" size=".05" fromto="0 0 0 0 -0.05 0" mass=".125" material="MatWheel" condim="4"/>
				<site size=".01" pos="0 -.05 .03"/>
				<site size=".01" pos="0 -.05 -.03"/>
				<site size=".01" pos="0 0 .03"/>
				<site size=".01" pos="0 0 -.03"/>
            </body>

			
        </body>
    </worldbody>
	
	
</mujoco>
